<?xml version="1.0"?>
<sdf version="1.6">
  <world name="default">
    <plugin
      filename="gz-sim-physics-system"
      name="gz::sim::systems::Physics">
    </plugin>
    <plugin
      filename="gz-sim-user-commands-system"
      name="gz::sim::systems::UserCommands">
    </plugin>
    <plugin
      filename="gz-sim-scene-broadcaster-system"
      name="gz::sim::systems::SceneBroadcaster">
    </plugin>
    <plugin
      filename="gz-sim-sensors-system"
      name="gz::sim::systems::Sensors">
      <render_engine>ogre2</render_engine>
    </plugin>
    <plugin
      filename="gz-sim-imu-system"
      name="gz::sim::systems::Imu">
    </plugin>

    <include>
      <uri>
        model://ground_plane
      </uri>
    </include>

    <!-- <include>
      <uri>
        model://Sky
      </uri>
    </include> -->

    <include>
      <uri>
        https://fuel.gazebosim.org/1.0/OpenRobotics/models/Sun
      </uri>
    </include>

    <scene>
      <ambient>0.5 0.5 0.5 1.0</ambient>
      <background>0.5 0.5 0.5 1.0</background>
      <grid>true</grid>
      <shadow>false</shadow>
      
      <sky></sky>
      <!-- <fog>
        <type>constant</type>
        <color>0.8 0.8 0.8 1.0</color>
        <density>0.01</density>
      </fog> -->
    </scene>

    

    <gui fullscreen='0'>
      <camera name='user_camera'>
        <pose frame=''>0.319654 -0.235002 9.29441 0 1.5138 0.009599</pose>
        <view_controller>orbit</view_controller>
        <projection_type>perspective</projection_type>
      </camera>
    </gui>

    <physics type="ode">
      <real_time_update_rate>1000.0</real_time_update_rate>
      <max_step_size>0.001</max_step_size>
      <real_time_factor>1</real_time_factor>
      <ode>
        <solver>
          <type>quick</type>
          <iters>150</iters>
          <precon_iters>0</precon_iters>
          <sor>1.400000</sor>
          <use_dynamic_moi_rescaling>1</use_dynamic_moi_rescaling>
        </solver>
        <constraints>
          <cfm>0.00001</cfm>
          <erp>0.2</erp>
          <contact_max_correcting_vel>2000.000000</contact_max_correcting_vel>
          <contact_surface_layer>0.01000</contact_surface_layer>
        </constraints>
      </ode>
    </physics>

    <model name='TruckBox'>
      <link name='body'>
        <pose>0 0 0 0 -0 0</pose>
        <visual name='visual'>
          <geometry>
            <mesh>
              <uri>https://fuel.gazebosim.org/1.0/openrobotics/models/truckbox/2/files/meshes/truck.obj</uri>
            </mesh>
          </geometry>
        </visual>
        <collision name='collision'>
          <geometry>
            <mesh>
              <uri>https://fuel.gazebosim.org/1.0/openrobotics/models/truckbox/2/files/meshes/truck.obj</uri>
            </mesh>
          </geometry>
        </collision>
        <inertial>
          <pose>0 0 0 0 -0 0</pose>
          <mass>1</mass>
          <inertia>
            <ixx>1</ixx>
            <ixy>0</ixy>
            <ixz>0</ixz>
            <iyy>1</iyy>
            <iyz>0</iyz>
            <izz>1</izz>
          </inertia>
        </inertial>
        <enable_wind>false</enable_wind>
      </link>
      <pose>4.51167 -2.73759 0.124316 -0 0 -3.09198</pose>
      <static>false</static>
      <self_collide>false</self_collide>
    </model>
    <model name='TruckBox_0'>
      <link name='body'>
        <pose>0 0 0 0 -0 0</pose>
        <visual name='visual'>
          <geometry>
            <mesh>
              <uri>https://fuel.gazebosim.org/1.0/openrobotics/models/truckbox/2/files/meshes/truck.obj</uri>
            </mesh>
          </geometry>
        </visual>
        <collision name='collision'>
          <geometry>
            <mesh>
              <uri>https://fuel.gazebosim.org/1.0/openrobotics/models/truckbox/2/files/meshes/truck.obj</uri>
            </mesh>
          </geometry>
        </collision>
        <inertial>
          <pose>0 0 0 0 -0 0</pose>
          <mass>1</mass>
          <inertia>
            <ixx>1</ixx>
            <ixy>0</ixy>
            <ixz>0</ixz>
            <iyy>1</iyy>
            <iyz>0</iyz>
            <izz>1</izz>
          </inertia>
        </inertial>
        <enable_wind>false</enable_wind>
      </link>
      <pose>-5.5959 4.75159 0.124314 -0 0 -1.58227</pose>
      <static>false</static>
      <self_collide>false</self_collide>
    </model>
    <model name='hatchback_blue'>
      <static>true</static>
      <link name='link'>
        <collision name='collision'>
          <pose>0 0 0 0 0 1.57079632679</pose>
          <geometry>
            <mesh>
              <scale>0.0254 0.0254 0.0254</scale>
              <uri>model://hatchback_blue/meshes/hatchback.obj</uri>
            </mesh>
          </geometry>
        </collision>
        <visual name='visual'>
          <pose>0 0 0 0 0 1.57079632679</pose>
          <geometry>
            <mesh>
              <scale>0.0254 0.0254 0.0254</scale>
              <uri>model://hatchback_blue/meshes/hatchback.obj</uri>
            </mesh>
          </geometry>
        </visual>
        <pose>0 0 0 0 -0 0</pose>
        <inertial>
          <pose>0 0 0 0 -0 0</pose>
          <mass>1</mass>
          <inertia>
            <ixx>1</ixx>
            <ixy>0</ixy>
            <ixz>0</ixz>
            <iyy>1</iyy>
            <iyz>0</iyz>
            <izz>1</izz>
          </inertia>
        </inertial>
        <enable_wind>false</enable_wind>
      </link>
      <pose>3.9083 6.29 0 0 -0 0</pose>
      <self_collide>false</self_collide>
    </model>
    <model name='hatchback_red'>
      <static>true</static>
      <link name='link'>
        <collision name='collision'>
          <pose>0 0 0 0 0 1.57079632679</pose>
          <geometry>
            <mesh>
              <scale>0.0255 0.0255 0.0255</scale>
              <uri>model://hatchback_red/meshes/hatchback.obj</uri>
            </mesh>
          </geometry>
        </collision>
        <visual name='visual'>
          <pose>0 0 0 0 0 1.57079632679</pose>
          <geometry>
            <mesh>
              <scale>0.0255 0.0255 0.0255</scale>
              <uri>model://hatchback_red/meshes/hatchback.obj</uri>
            </mesh>
          </geometry>
        </visual>
        <pose>0 0 0 0 -0 0</pose>
        <inertial>
          <pose>0 0 0 0 -0 0</pose>
          <mass>1</mass>
          <inertia>
            <ixx>1</ixx>
            <ixy>0</ixy>
            <ixz>0</ixz>
            <iyy>1</iyy>
            <iyz>0</iyz>
            <izz>1</izz>
          </inertia>
        </inertial>
        <enable_wind>false</enable_wind>
      </link>
      <pose>5.03834 -5.08104 0 0 0 -3.08509</pose>
      <self_collide>false</self_collide>
    </model>
    <model name='prius_hybrid'>
      <pose>-5.39957 -6.18385 0.136965 -0 0 -3.12761</pose>
      <link name='chassis'>
        <inertial>
          <mass>1326</mass>
          <pose>0 -0.266 0.48 0 -0 0</pose>
          <inertia>
            <ixx>2581.1300000000001</ixx>
            <ixy>0</ixy>
            <iyy>591.30799999999999</iyy>
            <ixz>0</ixz>
            <iyz>0</iyz>
            <izz>2681.9499999999998</izz>
          </inertia>
        </inertial>
        <visual name='chassis_visual'>
          <geometry>
            <mesh>
              <uri>https://fuel.gazebosim.org/1.0/openrobotics/models/prius hybrid/3/files/meshes/Hybrid.obj</uri>
              <scale>0.01 0.01 0.01</scale>
              <submesh>
                <name>Hybrid</name>
                <center>false</center>
              </submesh>
            </mesh>
          </geometry>
        </visual>
        <visual name='interior_visual'>
          <geometry>
            <mesh>
              <uri>https://fuel.gazebosim.org/1.0/openrobotics/models/prius hybrid/3/files/meshes/Hybrid.obj</uri>
              <scale>0.01 0.01 0.01</scale>
              <submesh>
                <name>Hybrid_Interior</name>
                <center>false</center>
              </submesh>
            </mesh>
          </geometry>
        </visual>
        <visual name='windows_visual'>
          <geometry>
            <mesh>
              <uri>https://fuel.gazebosim.org/1.0/openrobotics/models/prius hybrid/3/files/meshes/Hybrid.obj</uri>
              <scale>0.01 0.01 0.01</scale>
              <submesh>
                <name>Hybrid_Windows</name>
                <center>false</center>
              </submesh>
            </mesh>
          </geometry>
        </visual>
        <collision name='chassis'>
          <pose>0.0 0.05 0.625 0 0 0</pose>
          <geometry>
            <box>
              <size>1.7526 2.1 0.95</size>
            </box>
          </geometry>
          <surface>
            <friction>
              <ode/>
            </friction>
            <bounce/>
            <contact/>
          </surface>
        </collision>
        <collision name='front_bumper'>
          <pose>0.0 -2.0 0.458488 0.0 0 0</pose>
          <geometry>
            <box>
              <size>1.33728 0.48 0.566691</size>
            </box>
          </geometry>
          <surface>
            <friction>
              <ode/>
            </friction>
            <bounce/>
            <contact/>
          </surface>
        </collision>
        <collision name='hood'>
          <pose>0.0 -1.900842 0.676305 0.341247 0 0</pose>
          <geometry>
            <box>
              <size>1.59797 0.493107 0.265468</size>
            </box>
          </geometry>
          <surface>
            <friction>
              <ode/>
            </friction>
            <bounce/>
            <contact/>
          </surface>
        </collision>
        <collision name='windshield'>
          <pose>0.0 -0.875105 1.032268 0.335476 0 0</pose>
          <geometry>
            <box>
              <size>1.16838 1.65425 0.272347</size>
            </box>
          </geometry>
          <surface>
            <friction>
              <ode/>
            </friction>
            <bounce/>
            <contact/>
          </surface>
        </collision>
        <collision name='top_front'>
          <pose>0.0 0.161236 1.386042 0.135030 0 0</pose>
          <geometry>
            <box>
              <size>1.27915 0.625988 0.171868</size>
            </box>
          </geometry>
          <surface>
            <friction>
              <ode/>
            </friction>
            <bounce/>
            <contact/>
          </surface>
        </collision>
        <collision name='top_rear'>
          <pose>0.0 0.817696 1.360069 -0.068997 0 0</pose>
          <geometry>
            <box>
              <size>1.28513 0.771189 0.226557</size>
            </box>
          </geometry>
          <surface>
            <friction>
              <ode/>
            </friction>
            <bounce/>
            <contact/>
          </surface>
        </collision>
        <collision name='rear_window'>
          <pose>0.0 1.640531 1.175126 -0.262017 0 0</pose>
          <geometry>
            <box>
              <size>1.26785 1.11634 0.244286</size>
            </box>
          </geometry>
          <surface>
            <friction>
              <ode/>
            </friction>
            <bounce/>
            <contact/>
          </surface>
        </collision>
        <collision name='trunk'>
          <pose>0.0 1.637059 0.888180 0.0 0 0</pose>
          <geometry>
            <box>
              <size>1.78806 1.13899 0.482746</size>
            </box>
          </geometry>
          <surface>
            <friction>
              <ode/>
            </friction>
            <bounce/>
            <contact/>
          </surface>
        </collision>
        <collision name='back_bumper'>
          <pose>0.0 2.054454 0.577870 0.0 0 0</pose>
          <geometry>
            <box>
              <size>1.78165 0.512093 0.581427</size>
            </box>
          </geometry>
          <surface>
            <friction>
              <ode/>
            </friction>
            <bounce/>
            <contact/>
          </surface>
        </collision>
        <pose>0 0 0 0 -0 0</pose>
        <enable_wind>false</enable_wind>
      </link>
      <link name='steering_wheel'>
        <pose>0.355892 -0.627339 0.986322 -0.278867 1.29094 1.28134</pose>
        <inertial>
          <mass>1</mass>
          <inertia>
            <ixx>0.14583299999999999</ixx>
            <ixy>0</ixy>
            <ixz>0</ixz>
            <iyy>0.14583299999999999</iyy>
            <iyz>0</iyz>
            <izz>0.125</izz>
          </inertia>
          <pose>0 0 0 0 -0 0</pose>
        </inertial>
        <collision name='collision'>
          <geometry>
            <cylinder>
              <radius>0.178172</radius>
              <length>0.041845</length>
            </cylinder>
          </geometry>
          <surface>
            <contact>
              <ode>
                <min_depth>0.0030000000000000001</min_depth>
              </ode>
            </contact>
            <friction>
              <ode/>
            </friction>
            <bounce/>
          </surface>
        </collision>
        <visual name='visual'>
          <pose>0 0 0 1.302101 0 0</pose>
          <geometry>
            <mesh>
              <uri>https://fuel.gazebosim.org/1.0/openrobotics/models/prius hybrid/3/files/meshes/Hybrid.obj</uri>
              <scale>0.01 0.01 0.01</scale>
              <submesh>
                <name>Steering_Wheel</name>
                <center>true</center>
              </submesh>
            </mesh>
          </geometry>
        </visual>
        <enable_wind>false</enable_wind>
      </link>
      <link name='front_left_wheel'>
        <pose>0.76 -1.41 0.3 0 -0 -0</pose>
        <inertial>
          <mass>11</mass>
          <inertia>
            <ixx>0.58631200000000006</ixx>
            <ixy>0</ixy>
            <iyy>0.33552900000000002</iyy>
            <ixz>0</ixz>
            <iyz>0</iyz>
            <izz>0.33552900000000002</izz>
          </inertia>
          <pose>0 0 0 0 -0 0</pose>
        </inertial>
        <visual name='visual'>
          <pose>0.04 0.0 0.0 0 0 0</pose>
          <geometry>
            <mesh>
              <uri>https://fuel.gazebosim.org/1.0/openrobotics/models/prius hybrid/3/files/meshes/Hybrid.obj</uri>
              <scale>0.01 0.01 0.01</scale>
              <submesh>
                <name>Wheel_Front_Left_</name>
                <center>true</center>
              </submesh>
            </mesh>
          </geometry>
        </visual>
        <collision name='collision'>
          <pose>0.0 0.0 0.0 0 1.5707963267948966 0</pose>
          <geometry>
            <sphere>
              <radius>0.31264999999999998</radius>
            </sphere>
          </geometry>
          <surface>
            <friction>
              <ode>
                <mu>0.90000000000000002</mu>
                <mu2>0.90000000000000002</mu2>
                <slip1>0</slip1>
                <slip2>0</slip2>
              </ode>
            </friction>
            <contact>
              <ode>
                <min_depth>0.001</min_depth>
                <kp>1000000000</kp>
              </ode>
            </contact>
            <bounce/>
          </surface>
        </collision>
        <enable_wind>false</enable_wind>
      </link>
      <link name='front_right_wheel'>
        <pose>-0.76 -1.41 0.3 0 -0 -0</pose>
        <inertial>
          <mass>11</mass>
          <inertia>
            <ixx>0.58631200000000006</ixx>
            <ixy>0</ixy>
            <iyy>0.33552900000000002</iyy>
            <ixz>0</ixz>
            <iyz>0</iyz>
            <izz>0.33552900000000002</izz>
          </inertia>
          <pose>0 0 0 0 -0 0</pose>
        </inertial>
        <visual name='visual'>
          <pose>-0.04 0.0 0.0 0 0 0</pose>
          <pose>0 0 0.0 0 0 0</pose>
          <geometry>
            <mesh>
              <uri>https://fuel.gazebosim.org/1.0/openrobotics/models/prius hybrid/3/files/meshes/Hybrid.obj</uri>
              <scale>0.01 0.01 0.01</scale>
              <submesh>
                <name>Wheel_Front_Right</name>
                <center>true</center>
              </submesh>
            </mesh>
          </geometry>
        </visual>
        <collision name='collision'>
          <pose>0.0 0.0 0.0 0 1.5707963267948966 0</pose>
          <geometry>
            <sphere>
              <radius>0.31264999999999998</radius>
            </sphere>
          </geometry>
          <surface>
            <friction>
              <ode>
                <mu>0.90000000000000002</mu>
                <mu2>0.90000000000000002</mu2>
                <slip1>0</slip1>
                <slip2>0</slip2>
              </ode>
            </friction>
            <contact>
              <ode>
                <min_depth>0.001</min_depth>
                <kp>1000000000</kp>
              </ode>
            </contact>
            <bounce/>
          </surface>
        </collision>
        <enable_wind>false</enable_wind>
      </link>
      <link name='rear_left_wheel'>
        <pose>0.786 1.45 0.3 0 -0 0</pose>
        <inertial>
          <mass>11</mass>
          <inertia>
            <ixx>0.58631200000000006</ixx>
            <ixy>0</ixy>
            <iyy>0.33552900000000002</iyy>
            <ixz>0</ixz>
            <iyz>0</iyz>
            <izz>0.33552900000000002</izz>
          </inertia>
          <pose>0 0 0 0 -0 0</pose>
        </inertial>
        <visual name='visual'>
          <pose>0.04 0.0 0.0 0 0 0</pose>
          <geometry>
            <mesh>
              <uri>https://fuel.gazebosim.org/1.0/openrobotics/models/prius hybrid/3/files/meshes/Hybrid.obj</uri>
              <scale>0.01 0.01 0.01</scale>
              <submesh>
                <name>Wheel_Front_Left_</name>
                <center>true</center>
              </submesh>
            </mesh>
          </geometry>
        </visual>
        <collision name='collision'>
          <pose>0.0 0.0 0.0 0 1.5707963267948966 0</pose>
          <geometry>
            <sphere>
              <radius>0.31264999999999998</radius>
            </sphere>
          </geometry>
          <surface>
            <friction>
              <ode>
                <mu>1.1000000000000001</mu>
                <mu2>1.1000000000000001</mu2>
                <slip1>0</slip1>
                <slip2>0</slip2>
              </ode>
            </friction>
            <contact>
              <ode>
                <min_depth>0.001</min_depth>
                <kp>1000000000</kp>
              </ode>
            </contact>
            <bounce/>
          </surface>
        </collision>
        <enable_wind>false</enable_wind>
      </link>
      <link name='rear_right_wheel'>
        <pose>-0.786 1.45 0.3 0 -0 0</pose>
        <inertial>
          <mass>11</mass>
          <inertia>
            <ixx>0.58631200000000006</ixx>
            <ixy>0</ixy>
            <iyy>0.33552900000000002</iyy>
            <ixz>0</ixz>
            <iyz>0</iyz>
            <izz>0.33552900000000002</izz>
          </inertia>
          <pose>0 0 0 0 -0 0</pose>
        </inertial>
        <visual name='visual'>
          <pose>-0.04 0.0 0.0 0 0 0</pose>
          <geometry>
            <mesh>
              <uri>https://fuel.gazebosim.org/1.0/openrobotics/models/prius hybrid/3/files/meshes/Hybrid.obj</uri>
              <scale>0.01 0.01 0.01</scale>
              <submesh>
                <name>Wheel_Front_Right</name>
                <center>true</center>
              </submesh>
            </mesh>
          </geometry>
        </visual>
        <collision name='collision'>
          <pose>0.0 0.0 0.0 0 1.5707963267948966 0</pose>
          <geometry>
            <sphere>
              <radius>0.31264999999999998</radius>
            </sphere>
          </geometry>
          <surface>
            <friction>
              <ode>
                <mu>1.1000000000000001</mu>
                <mu2>1.1000000000000001</mu2>
                <slip1>0</slip1>
                <slip2>0</slip2>
              </ode>
            </friction>
            <contact>
              <ode>
                <min_depth>0.001</min_depth>
                <kp>1000000000</kp>
              </ode>
            </contact>
            <bounce/>
          </surface>
        </collision>
        <enable_wind>false</enable_wind>
      </link>
      <joint name='front_left_combined_joint' type='universal'>
        <pose>0 0 0 -0.087266 0 0</pose>
        <child>front_left_wheel</child>
        <parent>chassis</parent>
        <axis>
          <xyz>0 -0 1</xyz>
          <limit>
            <lower>-0.87270000000000003</lower>
            <upper>0.87270000000000003</upper>
            <effort>inf</effort>
            <velocity>inf</velocity>
            <stiffness>100000000</stiffness>
            <dissipation>1</dissipation>
          </limit>
          <dynamics>
            <spring_reference>0</spring_reference>
            <spring_stiffness>0</spring_stiffness>
            <damping>0</damping>
            <friction>0</friction>
          </dynamics>
        </axis>
        <axis2>
          <xyz>1 0 0</xyz>
          <limit>
            <lower>-10000000000000000</lower>
            <upper>10000000000000000</upper>
            <effort>inf</effort>
            <velocity>inf</velocity>
            <stiffness>100000000</stiffness>
            <dissipation>1</dissipation>
          </limit>
          <dynamics>
            <spring_reference>0</spring_reference>
            <spring_stiffness>0</spring_stiffness>
            <damping>0</damping>
            <friction>18.0474</friction>
          </dynamics>
        </axis2>
      </joint>
      <joint name='front_right_combined_joint' type='universal'>
        <pose>0 0 0 -0.087266 0 0</pose>
        <child>front_right_wheel</child>
        <parent>chassis</parent>
        <axis>
          <xyz>0 -0 1</xyz>
          <limit>
            <lower>-0.87270000000000003</lower>
            <upper>0.87270000000000003</upper>
            <effort>inf</effort>
            <velocity>inf</velocity>
            <stiffness>100000000</stiffness>
            <dissipation>1</dissipation>
          </limit>
          <dynamics>
            <spring_reference>0</spring_reference>
            <spring_stiffness>0</spring_stiffness>
            <damping>0</damping>
            <friction>0</friction>
          </dynamics>
        </axis>
        <axis2>
          <xyz>1 0 0</xyz>
          <limit>
            <lower>-10000000000000000</lower>
            <upper>10000000000000000</upper>
            <effort>inf</effort>
            <velocity>inf</velocity>
            <stiffness>100000000</stiffness>
            <dissipation>1</dissipation>
          </limit>
          <dynamics>
            <spring_reference>0</spring_reference>
            <spring_stiffness>0</spring_stiffness>
            <damping>0</damping>
            <friction>18.0474</friction>
          </dynamics>
        </axis2>
      </joint>
      <link name='rear_axle'>
        <pose>0 1.45 0.3 0 -0 0</pose>
        <inertial>
          <mass>30</mass>
          <inertia>
            <ixx>0.084375000000000006</ixx>
            <ixy>0</ixy>
            <iyy>4.64581</iyy>
            <ixz>0</ixz>
            <iyz>0</iyz>
            <izz>4.64581</izz>
          </inertia>
          <pose>0 0 0 0 -0 0</pose>
        </inertial>
        <visual name='visual'>
          <pose>0.0 0.0 0.0 0 1.5707963267948966 0</pose>
          <geometry>
            <cylinder>
              <length>1.357</length>
              <radius>0.074999999999999997</radius>
            </cylinder>
          </geometry>
          <material>
            <script>
              <name>Gazebo/Grey</name>
              <uri>file://media/materials/scripts/gazebo.material</uri>
            </script>
          </material>
        </visual>
        <enable_wind>false</enable_wind>
      </link>
      <joint name='rear_axle_joint' type='revolute'>
        <child>rear_axle</child>
        <parent>chassis</parent>
        <axis>
          <xyz>0 1 0</xyz>
          <limit>
            <lower>-0.050890600000000001</lower>
            <upper>0.050890600000000001</upper>
            <effort>inf</effort>
            <velocity>inf</velocity>
            <stiffness>100000000</stiffness>
            <dissipation>1</dissipation>
          </limit>
          <dynamics>
            <spring_reference>0</spring_reference>
            <spring_stiffness>20000</spring_stiffness>
            <damping>2000</damping>
            <friction>0</friction>
          </dynamics>
        </axis>
        <pose>0 0 0 0 -0 0</pose>
      </joint>
      <joint name='rear_left_wheel_joint' type='revolute'>
        <child>rear_left_wheel</child>
        <parent>rear_axle</parent>
        <axis>
          <xyz>1 0 0</xyz>
          <limit>
            <lower>-10000000000000000</lower>
            <upper>10000000000000000</upper>
            <effort>inf</effort>
            <velocity>inf</velocity>
            <stiffness>100000000</stiffness>
            <dissipation>1</dissipation>
          </limit>
          <dynamics>
            <spring_reference>0</spring_reference>
            <spring_stiffness>0</spring_stiffness>
            <damping>0</damping>
            <friction>12.031599999999999</friction>
          </dynamics>
        </axis>
        <pose>0 0 0 0 -0 0</pose>
      </joint>
      <joint name='rear_right_wheel_joint' type='revolute'>
        <child>rear_right_wheel</child>
        <parent>rear_axle</parent>
        <axis>
          <xyz>1 0 0</xyz>
          <limit>
            <lower>-10000000000000000</lower>
            <upper>10000000000000000</upper>
            <effort>inf</effort>
            <velocity>inf</velocity>
            <stiffness>100000000</stiffness>
            <dissipation>1</dissipation>
          </limit>
          <dynamics>
            <spring_reference>0</spring_reference>
            <spring_stiffness>0</spring_stiffness>
            <damping>0</damping>
            <friction>12.031599999999999</friction>
          </dynamics>
        </axis>
        <pose>0 0 0 0 -0 0</pose>
      </joint>
      <joint name='steering_joint' type='revolute'>
        <pose>-0.002 -0 0 0 -0 0</pose>
        <parent>chassis</parent>
        <child>steering_wheel</child>
        <axis>
          <xyz>0 -8.5e-05 1</xyz>
          <limit>
            <lower>-7.8499999999999996</lower>
            <upper>7.8499999999999996</upper>
            <effort>inf</effort>
            <velocity>inf</velocity>
            <stiffness>100000000</stiffness>
            <dissipation>1</dissipation>
          </limit>
          <dynamics>
            <spring_reference>0</spring_reference>
            <spring_stiffness>0</spring_stiffness>
            <damping>1</damping>
            <friction>0</friction>
          </dynamics>
        </axis>
        <physics>
          <ode>
            <cfm_damping>true</cfm_damping>
          </ode>
        </physics>
      </joint>
      <static>false</static>
      <self_collide>false</self_collide>
    </model>
    <model name='person_walking'>
      <link name='link'>
        <inertial>
          <pose>0 0 0.95 0 -0 0</pose>
          <mass>80</mass>
          <inertia>
            <ixx>27.82</ixx>
            <ixy>0</ixy>
            <ixz>0</ixz>
            <iyy>24.879999999999999</iyy>
            <iyz>0</iyz>
            <izz>4.5700000000000003</izz>
          </inertia>
        </inertial>
        <collision name='bottom'>
          <pose>0 0 0.01 0 0 0</pose>
          <geometry>
            <box>
              <size>0.35 0.75 0.02</size>
            </box>
          </geometry>
          <surface>
            <friction>
              <ode/>
            </friction>
            <bounce/>
            <contact/>
          </surface>
        </collision>
        <collision name='person'>
          <pose>0 0 -0.02 0 0 0</pose>
          <geometry>
            <mesh>
              <uri>https://fuel.gazebosim.org/1.0/openrobotics/models/walking person/3/files/meshes/walking.dae</uri>
            </mesh>
          </geometry>
        </collision>
        <visual name='visual'>
          <pose>0 0 -0.02 0 0 0</pose>
          <geometry>
            <mesh>
              <uri>https://fuel.gazebosim.org/1.0/openrobotics/models/walking person/3/files/meshes/walking.dae</uri>
            </mesh>
          </geometry>
        </visual>
        <pose>0 0 0 0 -0 0</pose>
        <enable_wind>false</enable_wind>
      </link>
      <pose>4.8716 0.305357 0.0 -0.002822 0.002708 -3.03868</pose>
      <static>false</static>
      <self_collide>false</self_collide>
    </model>
    <model name='MaleVisitorOnPhone'>
      <static>true</static>
      <link name='body'>
        <pose>0 0 0 0 -0 0</pose>
        <visual name='visual'>
          <geometry>
            <mesh>
              <uri>https://fuel.gazebosim.org/1.0/openrobotics/models/malevisitoronphone/2/files/meshes/MaleVisitorStatic.obj</uri>
            </mesh>
          </geometry>
        </visual>
        <collision name='collision'>
          <geometry>
            <mesh>
              <uri>https://fuel.gazebosim.org/1.0/openrobotics/models/malevisitoronphone/2/files/meshes/MaleVisitorStatic_Col.obj</uri>
            </mesh>
          </geometry>
        </collision>
        <inertial>
          <pose>0 0 0 0 -0 0</pose>
          <mass>1</mass>
          <inertia>
            <ixx>1</ixx>
            <ixy>0</ixy>
            <ixz>0</ixz>
            <iyy>1</iyy>
            <iyz>0</iyz>
            <izz>1</izz>
          </inertia>
        </inertial>
        <enable_wind>false</enable_wind>
      </link>
      <pose>-1.97568 -4.26549 0.0 0 -0 0.149277</pose>
      <self_collide>false</self_collide>
    </model>
    <model name='casual_female'>
      <static>true</static>
      <link name='link'>
        <collision name='box'>
          <pose>0 0 0.9 0 0 0</pose>
          <geometry>
            <box>
              <size>0.76 0.33 1.77</size>
            </box>
          </geometry>
          <surface>
            <friction>
              <ode/>
            </friction>
            <bounce/>
            <contact/>
          </surface>
        </collision>
        <visual name='visual'>
          <pose>0 0 0.02 0.04 0 0</pose>
          <geometry>
            <mesh>
              <uri>file:///home/alfredo/.ignition/fuel/fuel.gazebosim.org/openrobotics/models/casual female/4/meshes/casual_female.dae</uri>
            </mesh>
          </geometry>
        </visual>
        <pose>0 0 0 0 -0 0</pose>
        <inertial>
          <pose>0 0 0 0 -0 0</pose>
          <mass>1</mass>
          <inertia>
            <ixx>1</ixx>
            <ixy>0</ixy>
            <ixz>0</ixz>
            <iyy>1</iyy>
            <iyz>0</iyz>
            <izz>1</izz>
          </inertia>
        </inertial>
        <enable_wind>false</enable_wind>
      </link>
      <pose>-0.008778 3.06966 0.0 0 0 -0.37289</pose>
      <self_collide>false</self_collide>
    </model>
  </world>
</sdf>